Workbook

Sheet Scope Overview
A1: Work Breadown Structure
A2: Scope Overview
A3: Project Name: [project name]
A4: Contractor Name: Terraphase Engineering, Inc.
A5: Contractor Project Manager: Ryan Thompson
A6: Purchase Requsition Number:
A7: Release PO# [SAP]
A8: Period of Performance: October-November 2026
A9: SCE Environmental Section: Remediation
A10: SCE Project Manager: [WCI PM]
A11: GENERAL SCOPE OVERVIEW
A16: SCOPE OF WORK DESCRIPTION | C16: SUB TOTAL
A17: A | B17: AGENCY/THIRD PARTY/PRP ISSUES | C17: ='Budget Detail'!X23 -> 0
A19: B | B19: ENVIRONMENTAL SITE INVESTIGATION | C19: ='Budget Detail'!X38 -> 0
A21: C | B21: SITE MONITORING | C21: ='Budget Detail'!X40 -> 0
A23: D | B23: RISK ASSESSMENT | C23: ='Budget Detail'!X43 -> 0
A25: E | B25: FEASIBILITY / CORRECTIVE MEASURES STUDIES | C25: ='Budget Detail'!X49 -> 0
C26: ='Budget Detail'!X56 -> 0
A27: F | B27: REMEDIAL DESIGN
A29: G | B29: CONSTRUCTION | C29: ='Budget Detail'!X68 -> #VALUE!
A31: H | B31: OPERATIONS AND MAINTENANCE | C31: ='Budget Detail'!X78 -> 0
A33: I | B33: CLOSURE | C33: ='Budget Detail'!X85 -> 0
A35: J | B35: EXTERNAL PROJECT MANAGEMENT | C35: ='Budget Detail'!X91 -> 0
A37: K | B37: WCI SAMPLING | C37: ='WCI Budget Detail'!W22 -> 0
A38: Sampling of [media] in support of construction project.
A39: TOTAL | C39: ='Budget Detail'!X93 -> #VALUE!

Sheet WCI Budget Detail
A1: Work Breadown Structure
A2: Budget Detail
A3: ='Scope Overview'!A3 -> Project Name: [project name]
A4: ='Scope Overview'!A4 -> Contractor Name: Terraphase Engineering, Inc.
A5: ='Scope Overview'!A5 -> Contractor Project Manager: Ryan Thompson
A6: ='Scope Overview'!A6 -> Purchase Requsition Number:
A7: ='Scope Overview'!A7 -> Release PO# [SAP]
A8: ='Scope Overview'!A8 -> Period of Performance: October-November 2026
A9: ='Scope Overview'!A9 -> SCE Environmental Section: Remediation
A10: ='Scope Overview'!A10 -> SCE Project Manager: [WCI PM]
C11: (Enter negotiated hourly rates in the Contractor Rates Tab Only)
B13: WORK BREAKDOWN STRUCTURE | C13: Technical Expert | D13: Officer | E13: Principal / Director | F13: Project Manager | G13: Senior Engineer | H13: Project Engineer | I13: Senior Staff Engineer | J13: Staff Engineer | K13: Junior Engineer | L13: CADD | M13: Document Editor | N13: Senior Technician | O13: Technician | P13: Admin | Q13: Mileage | R13: Field Vehicle/Day | S13: Equipment | T13: Per Diem | U13: Vehicle Rental | V13: Lab / Contractor | W13: TOTAL
C14: ='Contractor Rates'!C4 -> 279 | D14: ='Contractor Rates'!C5 -> 272 | E14: ='Contractor Rates'!C6 -> 254 | F14: ='Contractor Rates'!C7 -> 237 | G14: ='Contractor Rates'!C8 -> 214 | H14: ='Contractor Rates'!C9 -> 198 | I14: ='Contractor Rates'!C10 -> 182 | J14: ='Contractor Rates'!C11 -> 165 | K14: ='Contractor Rates'!C12 -> 142 | L14: ='Contractor Rates'!C13 -> 132 | M14: ='Contractor Rates'!C14 -> 128 | N14: ='Contractor Rates'!C15 -> 138 | O14: ='Contractor Rates'!C16 -> 105 | P14: ='Contractor Rates'!C17 -> 85 | Q14: 0 | R14: 138 | S14: [Equip fee]
A15: KZ | B15: WCI SAMPLING
A16: K1 | B16: Sampling Activities (all media) | S16: [equip fee] | T16: 0 | U16: 0 | V16: 0 | W16: =C16*C$14+D16*D$14+E16*E$14+F16*F$14+G16*G$14+H16*H$14+I16*I$14+J16*J$14+K16*K$14++L16*L$14++M16*M$14+N16*N$14+O16*O$14+P16*P$14+Q16*Q$14+R16*R$14+S16+T16+U16+V16 -> #VALUE!
A17: C2 | B17: Laboratory | S17: 0 | T17: 0 | U17: 0 | V17: 0 | W17: =C17*C$14+D17*D$14+E17*E$14+F17*F$14+G17*G$14+H17*H$14+I17*I$14+J17*J$14+K17*K$14++L17*L$14++M17*M$14+N17*N$14+O17*O$14+P17*P$14+Q17*Q$14+R17*R$14+S17+T17+U17+V17 -> 0
A18: K2 | B18: Data Evaluation / Reporting | S18: 0 | T18: 0 | U18: 0 | V18: 0 | W18: =C18*C$14+D18*D$14+E18*E$14+F18*F$14+G18*G$14+H18*H$14+I18*I$14+J18*J$14+K18*K$14++L18*L$14++M18*M$14+N18*N$14+O18*O$14+P18*P$14+Q18*Q$14+R18*R$14+S18+T18+U18+V18 -> 0
A19: C4 | B19: Disposal Costs | S19: 0 | T19: 0 | U19: 0 | V19: 0 | W19: =C19*C$14+D19*D$14+E19*E$14+F19*F$14+G19*G$14+H19*H$14+I19*I$14+J19*J$14+K19*K$14++L19*L$14++M19*M$14+N19*N$14+O19*O$14+P19*P$14+Q19*Q$14+R19*R$14+S19+T19+U19+V19 -> 0
A20: K3 | B20: Travel / Other / Miscellaneous | S20: 0 | T20: 0 | U20: 0 | V20: 0 | W20: =C20*C$14+D20*D$14+E20*E$14+F20*F$14+G20*G$14+H20*H$14+I20*I$14+J20*J$14+K20*K$14++L20*L$14++M20*M$14+N20*N$14+O20*O$14+P20*P$14+Q20*Q$14+R20*R$14+S20+T20+U20+V20 -> 0
A21: K4 | B21: Project Management | S21: 0 | T21: 0 | U21: 0 | V21: 0 | W21: =C21*C$14+D21*D$14+E21*E$14+F21*F$14+G21*G$14+H21*H$14+I21*I$14+J21*J$14+K21*K$14++L21*L$14++M21*M$14+N21*N$14+O21*O$14+P21*P$14+Q21*Q$14+R21*R$14+S21+T21+U21+V21 -> 0
A22: KZ | B22: WCI SAMPLING TOTAL | C22: =SUBTOTAL(9,C16:C21)*C14 -> 0 | D22: =SUBTOTAL(9,D16:D21)*D14 -> 0 | E22: =SUBTOTAL(9,E16:E21)*E14 -> 0 | F22: =SUBTOTAL(9,F16:F21)*F14 -> 0 | G22: =SUBTOTAL(9,G16:G21)*G14 -> 0 | H22: =SUBTOTAL(9,H16:H21)*H14 -> 0 | I22: =SUBTOTAL(9,I16:I21)*I14 -> 0 | J22: =SUBTOTAL(9,J16:J21)*J14 -> 0 | ... R22: =SUBTOTAL(9,R16:R21)*R14 -> 0 | S22: =SUBTOTAL(9,S16:S21) -> 0 | T22: =SUBTOTAL(9,T16:T19) -> 0 | U22: =SUBTOTAL(9,U16:U19) -> 0 | V22: =SUBTOTAL(9,V16:V19) -> 0 | W22: =SUM(C22:V22) -> 0

Sheet Budget Detail
A1: Work Breakdown Structure | C1: For Change Orders Only
A2: Budget Detail | C2: Previously Authorized Amount
A3: ='Scope Overview'!A3 -> Project Name: [project name] | C3: New Rquested Total (Auto Calculates)
A4: ='Scope Overview'!A4 -> Contractor Name: Terraphase Engineering, Inc.
A5: ='Scope Overview'!A5 -> Contractor Project Manager: Ryan Thompson
A6: ='Scope Overview'!A6 -> Purchase Requsition Number:
A7: ='Scope Overview'!A7 -> Release PO# [SAP]
A8: ='Scope Overview'!A8 -> Period of Performance: October-November 2026
A9: ='Scope Overview'!A9 -> SCE Environmental Section: Remediation
A10: ='Scope Overview'!A10 -> SCE Project Manager: [WCI PM]
A13: For Change Orders, Please enter previously authorized total in Cell F2 of this Workbook Page
C14: (Enter negotiated hourly rates in the Contractor Rates Tab Only)
B16: WORK BREAKDOWN STRUCTURE | C16: Technical Expert | D16: Officer | E16: Principal / Director | F16: Project Manager | G16: Senior Engineer | H16: Project Engineer | I16: Senior Staff Engineer | J16: Staff Engineer | K16: Junior Engineer | L16: CADD | M16: Document Editor | N16: Senior Technician | O16: Technician | P16: Admin | Q16: Lump Sum Costs | R16: Mileage | S16: Field Vehicle/Day | T16: Equipment | U16: Per Diem | V16: Vehicle Rental | W16: Lab / Contractor | X16: TOTAL
C17: ='Contractor Rates'!C4 -> 279 | D17: ='Contractor Rates'!C5 -> 272 | E17: ='Contractor Rates'!C6 -> 254 | F17: ='Contractor Rates'!C7 -> 237 | G17: ='Contractor Rates'!C8 -> 214 | H17: ='Contractor Rates'!C9 -> 198 | I17: ='Contractor Rates'!C10 -> 182 | J17: ='Contractor Rates'!C11 -> 165 | K17: ='Contractor Rates'!C12 -> 142 | L17: ='Contractor Rates'!C13 -> 132 | M17: ='Contractor Rates'!C14 -> 128 | N17: ='Contractor Rates'!C15 -> 138 | O17: ='Contractor Rates'!C16 -> 105 | P17: ='Contractor Rates'!C17 -> 85 | Q17: ='Contractor Rates'!D17 -> 0 | R17: 0 | S17: 138 | T17: [equip fee]
A18: A | B18: AGENCY/THIRD PARTY/PRP ISSUES
A19: A1 | B19: PRP / 3rd Party Costs | T19: 0 | U19: 0 | V19: 0 | W19: 0 | X19: =C19*C$17+D19*D$17+E19*E$17+F19*F$17+G19*G$17+H19*H$17+I19*I$17+J19*J$17+K19*K$17++L19*L$17++M19*M$17+N19*N$17+O19*O$17+P19*P$17+R19*R$17+S19*S$17+T19+U19+V19+W19 -> 0
A20: A2 | B20: Agency Oversight Costs | T20: 0 | U20: 0 | V20: 0 | W20: 0 | X20: =C20*C$17+D20*D$17+E20*E$17+F20*F$17+G20*G$17+H20*H$17+I20*I$17+J20*J$17+K20*K$17++L20*L$17++M20*M$17+N20*N$17+O20*O$17+P20*P$17+R20*R$17+S20*S$17+T20+U20+V20+W20 -> 0
A21: A3 | B21: Agency Negotiations / Meetings | T21: 0 | U21: 0 | V21: 0 | W21: 0 | X21: =C21*C$17+D21*D$17+E21*E$17+F21*F$17+G21*G$17+H21*H$17+I21*I$17+J21*J$17+K21*K$17++L21*L$17++M21*M$17+N21*N$17+O21*O$17+P21*P$17+R21*R$17+S21*S$17+T21+U21+V21+W21 -> 0
A22: A4 | B22: Travel / Other / Miscellaneous | T22: 0 | U22: 0 | V22: 0 | W22: 0 | X22: =C22*C$17+D22*D$17+E22*E$17+F22*F$17+G22*G$17+H22*H$17+I22*I$17+J22*J$17+K22*K$17++L22*L$17++M22*M$17+N22*N$17+O22*O$17+P22*P$17+R22*R$17+S22*S$17+T22+U22+V22+W22 -> 0
A23: AZ | B23: AGENCY/THIRD PARTY/PRP ISSUES | C23: =SUBTOTAL(9,C19:C22)*C17 -> 0 | D23: =SUBTOTAL(9,D19:D22)*D17 -> 0 | E23: =SUBTOTAL(9,E19:E22)*E17 -> 0 | F23: =SUBTOTAL(9,F19:F22)*F17 -> 0 | G23: =SUBTOTAL(9,G19:G22)*G17 -> 0 | H23: =SUBTOTAL(9,H19:H22)*H17 -> 0 | I23: =SUBTOTAL(9,I19:I22)*I17 -> 0 | J23: =SUBTOTAL(9,J19:J22)*J17 -> 0 | ... S23: =SUBTOTAL(9,S19:S22)*S17 -> 0 | T23: =SUBTOTAL(9,T19:T22) -> 0 | U23: =SUBTOTAL(9,U19:U22) -> 0 | V23: =SUBTOTAL(9,V19:V22) -> 0 | W23: =SUBTOTAL(9,W19:W22) -> 0 | X23: =SUM(C23:W23) -> 0
A24: B | B24: ENVIRONMENTAL SITE INVESTIGATION
A25: B1 | B25: Scope Development (Workplan H&S, O&M, etc.) | T25: 0 | U25: 0 | V25: 0 | W25: 0 | X25: =C25*C$17+D25*D$17+E25*E$17+F25*F$17+G25*G$17+H25*H$17+I25*I$17+J25*J$17+K25*K$17++L25*L$17++M25*M$17+N25*N$17+O25*O$17+P25*P$17+R25*R$17+S25*S$17+T25+U25+V25+W25 -> 0
A26: B2 | B26: Field Investigation | S26: 1 | T26: [equip fee] | U26: 0 | V26: 0 | W26: 0 | X26: =C26*C$17+D26*D$17+E26*E$17+F26*F$17+G26*G$17+H26*H$17+I26*I$17+J26*J$17+K26*K$17++L26*L$17++M26*M$17+N26*N$17+O26*O$17+P26*P$17+R26*R$17+S26*S$17+T26+U26+V26+W26 -> #VALUE!
A27: B3 | B27: Laboratory | T27: 0 | U27: 0 | V27: 0 | W27: 0 | X27: =C27*C$17+D27*D$17+E27*E$17+F27*F$17+G27*G$17+H27*H$17+I27*I$17+J27*J$17+K27*K$17++L27*L$17++M27*M$17+N27*N$17+O27*O$17+P27*P$17+R27*R$17+S27*S$17+T27+U27+V27+W27 -> 0
A28: B4 | B28: Drilling | T28: 0 | U28: 0 | V28: 0 | W28: 0 | X28: =C28*C$17+D28*D$17+E28*E$17+F28*F$17+G28*G$17+H28*H$17+I28*I$17+J28*J$17+K28*K$17++L28*L$17++M28*M$17+N28*N$17+O28*O$17+P28*P$17+R28*R$17+S28*S$17+T28+U28+V28+W28 -> 0
A29: B5 | B29: RI Report | T29: 0 | U29: 0 | V29: 0 | W29: 0 | X29: =C29*C$17+D29*D$17+E29*E$17+F29*F$17+G29*G$17+H29*H$17+I29*I$17+J29*J$17+K29*K$17++L29*L$17++M29*M$17+N29*N$17+O29*O$17+P29*P$17+R29*R$17+S29*S$17+T29+U29+V29+W29 -> 0
A30: B6 | B30: Computer Modeling / Analysis | T30: 0 | U30: 0 | V30: 0 | W30: 0 | X30: =C30*C$17+D30*D$17+E30*E$17+F32*F$17+G30*G$17+H30*H$17+I30*I$17+J32*J$17+K30*K$17++L30*L$17++M30*M$17+N30*N$17+O30*O$17+P30*P$17+R30*R$17+S30*S$17+T30+U30+V30+W30 -> 0
A31: B7 | B31: Disposal Costs | T31: 0 | U31: 0 | V31: 0 | W31: 0 | X31: =C31*C$17+D31*D$17+E31*E$17+F31*F$17+G31*G$17+H31*H$17+I31*I$17+J31*J$17+K31*K$17++L31*L$17++M31*M$17+N31*N$17+O31*O$17+P31*P$17+R31*R$17+S31*S$17+T31+U31+V31+W31 -> 0
A32: B8 | B32: Travel / Other / Miscellaneous | T32: 0 | U32: 0 | V32: 0 | W32: 0 | X32: =C32*C$17+D32*D$17+E32*E$17+F32*F$17+G32*G$17+H32*H$17+I32*I$17+J32*J$17+K32*K$17++L32*L$17++M32*M$17+N32*N$17+O32*O$17+P32*P$17+R32*R$17+S32*S$17+T32+U32+V32+W32 -> 0
A33: BZ | B33: ENVIRONMENTAL SITE INVESTIGATION | C33: =SUBTOTAL(9,C25:C32)*C17 -> 0 | D33: =SUBTOTAL(9,D25:D32)*D17 -> 0 | E33: =SUBTOTAL(9,E25:E32)*E17 -> 0 | F33: =SUBTOTAL(9,F25:F32)*F17 -> 0 | G33: =SUBTOTAL(9,G25:G32)*G17 -> 0 | H33: =SUBTOTAL(9,H25:H32)*H17 -> 0 | I33: =SUBTOTAL(9,I25:I32)*I17 -> 0 | J33: =SUBTOTAL(9,J25:J32)*J17 -> 0 | ... S33: =SUBTOTAL(9,S25:S32)*S17 -> 138 | T33: =SUBTOTAL(9,T25:T32) -> 0 | U33: =SUBTOTAL(9,U25:U32) -> 0 | V33: =SUBTOTAL(9,V25:V32) -> 0 | W33: =SUBTOTAL(9,W25:W32) -> 0 | X33: =SUM(C33:W33) -> 138
A34: C | B34: SITE MONITORING
A35: C1 | B35: Sampling Activities (all media) | T35: 0 | U35: 0 | V35: 0 | W35: 0 | X35: =C35*C$17+D35*D$17+E35*E$17+F35*F$17+G35*G$17+H35*H$17+I35*I$17+J35*J$17+K35*K$17++L35*L$17++M35*M$17+N35*N$17+O35*O$17+P35*P$17+R35*R$17+S35*S$17+T35+U35+V35+W35 -> 0
A36: C2 | B36: Laboratory | T36: 0 | U36: 0 | V36: 0 | W36: 0 | X36: =C36*C$17+D36*D$17+E36*E$17+F36*F$17+G36*G$17+H36*H$17+I36*I$17+J36*J$17+K36*K$17++L36*L$17++M36*M$17+N36*N$17+O36*O$17+P36*P$17+R36*R$17+S36*S$17+T36+U36+V36+W36 -> 0
A37: C3 | B37: Data Evaluation / Reporting | T37: 0 | U37: 0 | V37: 0 | W37: 0 | X37: =C37*C$17+D37*D$17+E37*E$17+F37*F$17+G37*G$17+H37*H$17+I37*I$17+J37*J$17+K37*K$17++L37*L$17++M37*M$17+N37*N$17+O37*O$17+P37*P$17+R37*R$17+S37*S$17+T37+U37+V37+W37 -> 0
A38: C4 | B38: Disposal Costs | T38: 0 | U38: 0 | V38: 0 | W38: 0 | X38: =C38*C$17+D38*D$17+E38*E$17+F38*F$17+G38*G$17+H38*H$17+I38*I$17+J38*J$17+K38*K$17++L38*L$17++M38*M$17+N38*N$17+O38*O$17+P38*P$17+R38*R$17+S38*S$17+T38+U38+V38+W38 -> 0
A39: C5 | B39: Travel / Other / Miscellaneous | T39: 0 | U39: 0 | V39: 0 | W39: 0 | X39: =C39*C$17+D39*D$17+E39*E$17+F39*F$17+G39*G$17+H39*H$17+I39*I$17+J39*J$17+K39*K$17++L39*L$17++M39*M$17+N39*N$17+O39*O$17+P39*P$17+R39*R$17+S39*S$17+T39+U39+V39+W39 -> 0
A40: CZ | B40: SITE MONITORING | C40: =SUBTOTAL(9,C35:C38)*C17 -> 0 | D40: =SUBTOTAL(9,D35:D38)*D17 -> 0 | E40: =SUBTOTAL(9,E35:E38)*E17 -> 0 | F40: =SUBTOTAL(9,F35:F39)*F17 -> 0 | G40: =SUBTOTAL(9,G35:G39)*G17 -> 0 | H40: =SUBTOTAL(9,H35:H39)*H17 -> 0 | I40: =SUBTOTAL(9,I35:I39)*I17 -> 0 | J40: =SUBTOTAL(9,J35:J39)*J17 -> 0 | K40: =SUBTOTAL(9,K35:K39)*K17 -> 0 | L40: =SUBTOTAL(9,L35:L39)*L17 -> 0 | M40: =SUBTOTAL(9,M35:M39)*M17 -> 0 | ... S40: =SUBTOTAL(9,S35:S39)*S17 -> 0 | T40: =SUBTOTAL(9,T35:T39) -> 0 | U40: =SUBTOTAL(9,U35:U39) -> 0 | V40: =SUBTOTAL(9,V35:V39) -> 0 | W40: =SUBTOTAL(9,W35:W39) -> 0 | X40: =SUM(C40:W40) -> 0
A41: D | B41: RISK ASSESSMENT
A42: D1 | B42: Risk Assessment Analysis / Report | T42: 0 | U42: 0 | V42: 0 | W42: 0 | X42: =C42*C$17+D42*D$17+E42*E$17+F42*F$17+G42*G$17+H42*H$17+I42*I$17+J42*J$17+K42*K$17++L42*L$17++M42*M$17+N42*N$17+O42*O$17+P42*P$17+R42*R$17+S42*S$17+T42+U42+V42+W42 -> 0
A43: DZ | B43: RISK ASSESSMENT | C43: =SUBTOTAL(9,C42:C42)*C17 -> 0 | D43: =SUBTOTAL(9,D42:D42)*D17 -> 0 | E43: =SUBTOTAL(9,E42:E42)*E17 -> 0 | F43: =SUBTOTAL(9,F42:F42)*F17 -> 0 | G43: =SUBTOTAL(9,G42:G42)*G17 -> 0 | H43: =SUBTOTAL(9,H42:H42)*H17 -> 0 | I43: =SUBTOTAL(9,I42:I42)*I17 -> 0 | J43: =SUBTOTAL(9,J42:J42)*J17 -> 0 | ... S43: =SUBTOTAL(9,S42:S42)*S17 -> 0 | T43: =SUBTOTAL(9,T42:T42) -> 0 | U43: =SUBTOTAL(9,U42:U42) -> 0 | V43: =SUBTOTAL(9,V42:V42) -> 0 | W43: =SUBTOTAL(9,W42:W42) -> 0 | X43: =SUM(C43:W43) -> 0
...

Sheet Contractor Rates
B1: Contractors to enter rates on this tab. Rates will autopopulate onto the Budget detail and Monthy Forecast Tab.
B3: Job Category | C3: Rate/hr
B4: Technical Expert | C4: 279
B5: Officer | C5: 272
B6: Principal/Director | C6: 254
B7: Project Manager | C7: 237
B8: Senior Engineer | C8: 214
B9: Project Engineer | C9: 198
B10: Senior Staff Engineer | C10: 182
B11: Staff Engineer | C11: 165
B12: Junior Engineer | C12: 142
B13: CADD Specialist | C13: 132
B14: Document Editor | C14: 128
B15: Senior Field Technician | C15: 138
... B17: Admin II | C17: 85
B19: EQUIPMENT | C19: RATE
C20: DAY | D20: WEEK | E20: MONTH
B21: Company Truck | C21: 138 | D21: 414 | E21: 1242 | G21: 138
B22: Company Truck 4x4 | C22: 157 | D22: 471 | E22: 1413
B23: Rental Car | C23: Actual Rental Cost
B24: Rental Truck | C24: Actual Rental Cost
B25: Trimble GPS | C25: Actual Rental Cost
B26: Trimble Antennae | C26: Actual Rental Cost
B27: RKI Methane Gas Meter (or similar) | C27: Actual Rental Cost
B28: 4-gas meter | C28: Actual Rental Cost
B29: Helium Shroud | C29: 57 | D29: 228 | E29: 912
B30: Mobile Laboratory (8260) | C30: Actual Subcontractor Cost
B31: Mobile Laboratory (TO-15) | C31: Actual Subcontractor Cost
B32: PID (ppm level) | C32: Actual Rental Cost
B33: PID (ppb level) | C33: Actual Rental Cost
B34: XRF | C34: Actual Rental Cost
B35: Grundfos or other down well pump | C35: Actual Rental Cost
B36: Low Flow Bladder Pump | C36: Actual Rental Cost
B37: Low Flow Pump Controller | C37: Actual Rental Cost
B38: Water Level Indicator (Solinst or similar) | C38: Actual Rental Cost
B39: Water/Interface Indicator (Solinst of similar) | C39: Actual Rental Cost
B40: Horiba U-42 or Similar | C40: Actual Rental Cost
B41: Peristaltic Pump | C41: Actual Rental Cost
B42: Soil Vapor Sampling Pump | C42: 70 | D42: 210 | E42: 630
B43: PM10 Dust Monitor | C43: Actual Rental Cost
...

Sheet ESA Rates
A3: Type of Work | B3: Proposed Pricing | C3: Description
A4: Typical Phase I ESA (lump sum) | B4: 0 | C4: 1. Scope follows AAI & latest ASTM E 1527 2. Schedule: Draft report provided within 4 weeks. 3. Location: baseline assumption is < 50 mile radius of Rosemead, CA 4. Includes: record search package (database, aerials, topos, lien and title search).
A5: Additional parcel – title and lien search | B5: 0 | C5: Per parcel title/lien search, when more than one APN
A6: Phase I Quick turnaround | B6: 0 | C6: <12 Days* to draft
A8: High-Level Screen ESA (lump sum) | B8: 0 | C8: 1. Scope generally follows AAI & latest ASTM E 1527. Exceptions: no owner/tenant interviews if unavailable, site visit may be limited to public access areas, no title/lien report for SCE owned properties. 2. Schedule: Draft report provided within 4 weeks. 3. Location: baseline assumption is < 50 mile radius of Rosemead, CA 4. Includes record search package. Assumes that the property is SCE owned and does not include a lien/title report.
A9: Title and lien search | B9: 0 | C9: Title and lien search not required for SCE owned properties. Fee to be added when title/lien search specifically requested. Per APN fee.
A10: HLS Quick turnaround | B10: 0 | C10: <12 Days* to draft
A12: Typical Low Level Screen ESA (lump sum) | B12: 0 | C12: 1. Site visit from publically accessible location or with an SCE representative, when appropriate. 2. Field visit/reconnaissance 3. Review free and readily available public records with regards to the site and adjoining properties. Obtain and review aerial photos and include as attachment to the LLS report. 4. Schedule: Draft report provided within 2 weeks. 5. Final letter report (include figures and photos). SCE PM to be notified when REC(s) identified so that sampling can be evaluated as soon as possible. 6. Location: baseline assumption < 50 mile radius of Rosemead, CA
A13: Quick turnaround | B13: 0 | C13: <5 Days* to draft
A15: >50 and ≤150 miles from Rosemead1 | B15: 0 | C15: From 2244 Walnut Grove, Rosemead. Includes mileage, fuel, meals and other incidentals.
A16: >150 and ≤250 miles from Rosemead | B16: 0 | C16: From 2244 Walnut Grove, Rosemead. Mileage included. When hotel is needed due to overnight stay, use per diem rate.
A18: Desktop Review | B18: 0 | C18: 1. Review of Geotracker, Envirostor, and Wellfinder for releases at the site address or on the adjoining properties. 2. Excel summary table of findings. 3. Schedule: 1 to 2 weeks.
A19: 10 site baseline | B19: 0 | C19: Assumes group of 10 sites will be requested together and that each site review will take an average of 15 to 20 minutes to complete
A20: Each additional site | B20: 0
